Workbook

Sheet README
A1: Northlight Software: driver-based planning model
A2: Assumption set v1.3. Generated by run_model.py; every number in this file comes from the model outputs.
A4: How to read this workbook
A5: 1. Assumptions: every driver, its value in each scenario, and whether it is anchored on a published benchmark, derived from a published rate table, or a judgment call.
A6: 2. Change log: what changed since the FY2026 budget was locked (v1.0), when, by whom and why. Snapshot + log = current values.
A7: 3. Actuals P&L and Budget FY2026: monthly detail. Yellow cells are values from the model; blue cells are Excel formulas you can click into.
A8: 4. Bridge YTD: January to August 2026 actual versus budget, by driver component. Impact is the effect on EBITDA, favorable positive. The components sum to the EBITDA variance.
A9: 5. The three scenario sheets hold the recommended option: P&L, ARR roll-forward, cloud and cash, with subtotals and the cash roll-forward as formulas.
A10: 6. Workforce: FTE and people cost per month by function and location for the recommended option, base scenario.
A11: 7. Checks: every formula subtotal recomputed against the model value. All differences must be zero.
A13: Conventions
A14: Revenue = closing ARR / 12. Net revenue retention is all-in (includes the January price increase). Cloud cost = min(units, commitment) x price x (1 - discount) + overage x price + fixed.
... A19: Guardrails: downside runway at least 18 months in every month; base gross margin at least 74% in every month.

Sheet Assumptions
A1: One row per driver. source_type: benchmark = published survey figure (named), derived = computed from a published rate table, judgment = own call.
A3: id | B3: category | C3: name | D3: unit | E3: base | F3: upside | G3: downside | H3: source_type | I3: source
A4: logos_per_ramped_ae_month | B4: revenue | C4: New customers won per fully ramped account executive per month | D4: logos/AE/month | E4: 0.9 | F4: 1.1 | G4: 0.5 | H4: judgment | I4: Base set at the trailing 2026 actual (0.92). Downside is a 45% productivity shortfall (pipeline does not rebuild). No external source.
A5: initial_acv_usd | B5: revenue | C5: Annual contract value of a new Platform customer | D5: USD/year | E5: 38000 | F5: 38000 | G5: 38000 | H5: judgment | I5: Chosen inside the USD 25k-50k ACV band so retention benchmarks for that band apply (SaaS Capital, Research Brief 32, 2025).
A6: nrr_annual | B6: revenue | C6: Net revenue retention (annual all-in including the January price increase) on the Platform base | D6: ratio | E6: 1.05 | F6: 1.1 | G6: 0.96 | H6: benchmark | I6: SaaS Capital, 2025 B2B SaaS Retention Benchmarks (Research Brief 32, 1,000+ companies): median NRR 102% for USD 25k-50k ACV, 104% for USD 50k-100k, 101% overall. Base 105% sits at the top of that median range; downside 96% sits just below the 25th percentile for USD 25k-50k ACV (97%).
A7: grr_annual | B7: revenue | C7: Gross revenue retention (annual) | D7: ratio | E7: 0.9 | F7: 0.92 | G7: 0.86 | H7: benchmark | I7: SaaS Capital, 2025 B2B SaaS Retention Benchmarks: median GRR 91% for USD 25k-50k ACV, 90% overall. Downside 86% is a judgment call below the median.
A8: price_increase_pct_jan | B8: revenue | C8: Price increase applied to existing Platform ARR every January | D8: ratio | E8: 0.05 | F8: 0.07 | G8: 0.03 | H8: judgment | I8: Company pricing policy assumption. No external source.
A9: attach_gain_pts_month | B9: revenue | C9: Monthly gain in the Insights add-on attach rate | D9: percentage points/month | E9: 0.6 | F9: 0.9 | G9: 0.2 | H9: judgment | I9: Product roadmap assumption. No external source.
A10: attach_rate_cap | B10: revenue | C10: Ceiling on the Insights attach rate | D10: ratio | E10: 0.45 | F10: 0.45 | G10: 0.45 | H10: judgment | I10: Product assumption. No external source.
A11: insights_usage_growth_month | B11: revenue | C11: Monthly growth in Insights revenue per customer from usage | D11: ratio/month | E11: 0.01 | F11: 0.015 | G11: 0.005 | H11: judgment | I11: Usage-based pricing assumption. No external source.
A12: ae_ramp_months | B12: revenue | C12: Months for a new account executive to reach full productivity | D12: months | E12: 4 | F12: 4 | G12: 4 | H12: judgment | I12: Common sales-planning convention. No external source.
A13: csm_ramp_months | B13: cost_of_revenue | C13: Months for a new customer success manager to carry a full book | D13: months | E13: 2 | F13: 2 | G13: 2 | H13: judgment | I13: Planning convention. No external source.
A14: customers_per_csm | B14: cost_of_revenue | C14: Customers carried per fully ramped customer success manager | D14: customers/CSM | E14: 45 | F14: 45 | G14: 45 | H14: judgment | I14: Coverage-ratio assumption for a mid-market book. No external source.
A15: cloud_units_per_platform_customer | B15: cost_of_revenue | C15: Compute units consumed per Platform customer per month | D15: units/customer/month | E15: 200 | F15: 200 | G15: 200 | H15: judgment | I15: Internal usage metric. No external source.
... A42: materiality_abs_override_usd | B42: materiality | C42: Bridge component is material above this absolute impact regardless of percentage | D42: USD | E42: 100000 | F42: 100000 | G42: 100000 | H42: judgment | I42: Reporting policy. No external source.

Sheet Change log
A1: Every change to assumptions.csv since v1.0. Replaying this log onto the v1.0 snapshot reproduces the current file (tested).
A3: version | B3: date | C3: assumption_id | D3: scenario | E3: old_value | F3: new_value | G3: changed_by | H3: reason
A4: 1.1 | B4: 2026-04-14 | C4: nrr_annual | D4: base | E4: 1.06 | F4: 1.05 | G4: Alan Vourc'h (FP&A) | H4: Q1 2026 churn review: SMB logo churn ran above budget for three consecutive months; net retention re-based to the trailing actual
A5: 1.1 | B5: 2026-04-14 | C5: logos_per_ramped_ae_month | D5: base | E5: 1.10 | F5: 0.90 | G5: Alan Vourc'h (FP&A) | H5: Q1 2026 new logos per ramped account executive ran at 0.92 against a budget of 1.10; base reset to the trailing actual (0.90)
A6: 1.2 | B6: 2026-07-08 | C6: cloud_units_per_insights_customer | D6: all | E6: 1500 | F6: 2000 | G6: Alan Vourc'h (FP&A) | H6: Insights customers' data volumes stepped up about 30% from March 2026; unit consumption re-based on April to June actuals
A7: 1.2 | B7: 2026-07-08 | C7: marketing_program_cost_per_new_logo | D7: base | E7: 28000 | F7: 30000 | G7: Alan Vourc'h (FP&A) | H7: H1 2026 programme spend per new logo ran at 30.7k including the May conference; base re-based
A8: 1.3 | B8: 2026-09-10 | C8: min_runway_months_downside | D8: all | E8: 12 | F8: 18 | G8: Alan Vourc'h (FP&A) | H8: Board asked for 18 months of downside runway after the March 2026 Series C extension (USD 25M)
A9: 1.3 | B9: 2026-09-10 | C9: cloud_unit_price_usd | D9: downside | E9: 0.44 | F9: 0.46 | G9: Alan Vourc'h (FP&A) | H9: Provider announced a list-price change on the instance family used for Insights workloads; the downside now carries it

Sheet Locations
A1: location | B1: employer_tax_rate | C1: benefits_rate | D1: rent_per_head_month_usd | E1: source_type | F1: source
A2: Montreal | B2: 0.11 | C2: 0.06 | D2: 450 | E2: derived | F2: Employer tax rate derived from Raymond Chabot Grant Thornton Tax News 930R4 (February 2026): QPP employer 6.30% on earnings from CAD 3,500 to 74,600 plus 4.00% on 74,600 to 85,000; QPIP employer 0.602% to CAD 103,000; EI employer (Quebec) 1.82% to CAD 68,900; Health Services Fund 4.26% for total payroll of CAD 7.8M or more. At a CAD 110k salary these total about 10.8%; CNESST (industry-rated) approximated at 0.4%. Benefits and rent are judgment calls.
A3: Paris | B3: 0.42 | C3: 0.05 | D3: 600 | E3: derived | F3: PwC Worldwide Tax Summaries, France, Other taxes: employer share of social contributions is about 45% of gross salary on average, declining as salary rises above the ceilings. 42% used for cadre-level technology salaries: own judgment. Benefits (mutuelle, meal vouchers) and rent are judgment calls.
A4: Austin | B4: 0.085 | C4: 0.14 | D4: 500 | E4: derived | F4: IRS Tax Topic 751 (2026): employer Social Security 6.2% up to the USD 184,500 wage base and Medicare 1.45% uncapped. FUTA and Texas SUTA approximated at 0.85%: own judgment. Benefits rate (health insurance heavy) and rent are judgment calls.

Sheet Salary table
A1: Annual salary in USD by role and location; sales_role = commission plan, no bonus accrual.
A3: role | B3: function | C3: cost_bucket | D3: sales_role | E3: Montreal | F3: Paris | G3: Austin
A4: Software Engineer | B4: R&D | C4: R&D | D4: FALSE | E4: 95000 | F4: 80000 | G4: 135000
A5: Senior Software Engineer | B5: R&D | C5: R&D | D5: FALSE | E5: 125000 | F5: 105000 | G5: 175000
A6: Engineering Manager | B6: R&D | C6: R&D | D6: FALSE | E6: 150000 | F6: 130000 | G6: 200000
A7: Product Manager | B7: R&D | C7: R&D | D7: FALSE | E7: 120000 | F7: 100000 | G7: 160000
A8: Product Designer | B8: R&D | C8: R&D | D8: FALSE | E8: 100000 | F8: 85000 | G8: 140000
A9: Data Engineer | B9: R&D | C9: R&D | D9: FALSE | E9: 115000 | F9: 95000 | G9: 155000
A10: Site Reliability Engineer | B10: Customer Operations | C10: COGS | D10: FALSE | E10: 120000 | F10: 105000 | G10: 165000
A11: Customer Success Manager | B11: Customer Operations | C11: COGS | D11: FALSE | E11: 75000 | F11: 65000 | G11: 90000
A12: Support Engineer | B12: Customer Operations | C12: COGS | D12: FALSE | E12: 65000 | F12: 55000 | G12: 75000
A13: Account Executive | B13: S&M | C13: S&M | D13: TRUE | E13: 90000 | F13: 80000 | G13: 110000
A14: Sales Development Rep | B14: S&M | C14: S&M | D14: TRUE | E14: 55000 | F14: 48000 | G14: 65000
A15: Marketing Manager | B15: S&M | C15: S&M | D15: FALSE | E15: 95000 | F15: 80000 | G15: 120000
... A18: Executive | B18: G&A | C18: G&A | D18: FALSE | E18: 240000 | F18: 220000 | G18: 280000

Sheet Hiring plans
A1: phased and front_loaded are the candidate plans; fy2026_budget is the plan inside the FY2026 budget.
A3: plan_id | B3: role | C3: location | D3: start_month | E3: count | F3: rationale
A4: phased | B4: Senior Software Engineer | C4: Montreal | D4: 2026-10 | E4: 2 | F4: Platform reliability squad
A5: phased | B5: Software Engineer | C5: Montreal | D5: 2026-11 | E5: 2 | F5: Platform reliability squad
A6: phased | B6: Software Engineer | C6: Paris | D6: 2026-11 | E6: 2 | F6: Insights data pipeline squad
A7: phased | B7: Data Engineer | C7: Paris | D7: 2027-01 | E7: 2 | F7: Insights data pipeline squad
A8: phased | B8: Senior Software Engineer | C8: Paris | D8: 2027-02 | E8: 1 | F8: Insights data pipeline squad lead
A9: phased | B9: Software Engineer | C9: Montreal | D9: 2027-03 | E9: 2 | F9: Integrations squad
A10: phased | B10: Product Manager | C10: Montreal | D10: 2027-01 | E10: 1 | F10: Insights product owner
A11: phased | B11: Software Engineer | C11: Paris | D11: 2027-05 | E11: 2 | F11: Integrations squad
A12: phased | B12: Account Executive | C12: Austin | D12: 2026-10 | E12: 1 | F12: Mid-market pod
A13: phased | B13: Account Executive | C13: Austin | D13: 2027-01 | E13: 2 | F13: Mid-market pod
A14: phased | B14: Account Executive | C14: Austin | D14: 2027-04 | E14: 1 | F14: Mid-market pod
A15: phased | B15: Sales Development Rep | C15: Austin | D15: 2027-01 | E15: 2 | F15: Pipeline coverage for new AEs
... A42: fy2026_budget | B42: Finance & Operations | C42: Montreal | D42: 2026-02 | E42: 1 | F42: FY2026 budget: billing operations

Sheet Options
A1: One row per option: guardrail results and headline outcomes. Feasible = both guardrails hold.
A3: option_id | B3: label | C3: downside_runway_min | D3: runway_ok | E3: base_gm_min | F3: gm_ok | G3: feasible | H3: base_arr_end | I3: base_cum_burn | J3: upside_arr_end | K3: downside_arr_end | L3: downside_cash_min
A4: hold_ondemand | B4: Hold hiring; cloud on demand | C4: 43.748582 | D4: TRUE | E4: 0.72860101 | F4: FALSE | G4: FALSE | H4: 38325017 | I4: 4149447.6 | J4: 44853935 | K4: 28548915 | L4: 17045571
A5: hold_commit | B5: Hold hiring; one-year cloud commitment | C5: 47.807616 | D5: TRUE | E5: 0.74839602 | F5: TRUE | G5: TRUE | H5: 38325017 | I5: 3339990.7 | J5: 44853935 | K5: 28548915 | L5: 17805272
A6: phased_ondemand | B6: Phased plan; cloud on demand | C6: 20.648966 | D6: TRUE | E6: 0.72860101 | F6: FALSE | G6: FALSE | H6: 40498712 | I6: 8619868.1 | J6: 47700306 | K6: 29686367 | L6: 12686738
A7: phased_commit | B7: Phased plan; one-year cloud commitment | C7: 23.282208 | D7: TRUE | E7: 0.74839602 | F7: TRUE | G7: TRUE | H7: 40498712 | I7: 7810224.1 | J7: 47700306 | K7: 29686367 | L7: 13466842
A8: front_ondemand | B8: Front-loaded plan with Insights contractors; cloud on demand | C8: 14.662368 | D8: FALSE | E8: 0.72860101 | F8: FALSE | G8: FALSE | H8: 42210227 | I8: 11446438 | J8: 49826907 | K8: 30601464 | L8: 9891945.8
A9: front_commit | B9: Front-loaded plan with Insights contractors; one-year cloud commitment | C9: 16.895252 | D9: FALSE | E9: 0.74839602 | F9: TRUE | G9: FALSE | H9: 42210227 | I9: 10636616 | J9: 49826907 | K9: 30601464 | L9: 10685919

Sheet Option grid
A1: Every option under every scenario: 18 runs of the same engine.
A3: option_id | B3: scenario | C3: arr_end | D3: arr_growth | E3: revenue_18m | F3: gross_profit_18m | G3: ebitda_18m | H3: cum_burn | I3: cash_end | J3: cash_min | K3: runway_min | L3: gm_min | M3: gm_avg | N3: fte_end | O3: rd_fte_end | P3: cloud_18m | Q3: stranded_cost_18m | R3: plan_hires | S3: plan_hire_cost_18m
A4: hold_ondemand | B4: base | C4: 38325017 | D4: 0.58027777 | E4: 46835089 | F4: 35361605 | G4: -4970369.1 | H4: 4149447.6 | I4: 20600832 | J4: 20074090 | K4: 36.414583 | L4: 0.72860101 | M4: 0.75502375 | N4: 139.16 | O4: 70.56 | P4: 4225935.9 | Q4: 0 | R4: 0 | S4: 0
A5: hold_ondemand | B5: upside | C5: 44853935 | D5: 0.84948846 | E5: 51311657 | F5: 39068261 | G5: -2519727 | H5: 1324951.9 | I5: 23425327 | J5: 21087638 | K5: 34.22913 | L5: 0.72940885 | M5: 0.76139153 | N5: 141.12 | O5: 70.56 | P5: 4689592.7 | Q5: 0 | R5: 2 | S5: 106396.7
A6: hold_ondemand | B6: downside | C6: 28548915 | D6: 0.17717407 | E6: 39610106 | F6: 29144874 | G6: -7955357.6 | H6: 7704708.7 | I6: 17045571 | J6: 17045571 | K6: 43.748582 | L6: 0.72652001 | M6: 0.7357939 | N6: 139.16 | O6: 70.56 | P6: 3542807 | Q6: 0 | R6: 0 | S6: 0
A7: hold_commit | B7: base | C7: 38325017 | D7: 0.58027777 | E7: 46835089 | F7: 36171062 | G7: -4160912.3 | H7: 3339990.7 | I7: 21410288 | J7: 20715215 | K7: 38.886526 | L7: 0.74839602 | M7: 0.77230687 | N7: 139.16 | O7: 70.56 | P7: 3416479 | Q7: 42596.581 | R7: 0 | S7: 0
A8: hold_commit | B8: upside | C8: 44853935 | D8: 0.84948846 | E8: 51311657 | F8: 39875437 | G8: -1712550.8 | H8: 517775.74 | I8: 24232503 | J8: 21537632 | K8: 36.446065 | L8: 0.7493189 | M8: 0.77712238 | N8: 141.12 | O8: 70.56 | P8: 3882416.5 | Q8: 26182.643 | R8: 2 | S8: 106396.7
A9: hold_commit | B9: downside | C9: 28548915 | D9: 0.17717407 | E9: 39610106 | F9: 29904576 | G9: -7195655.9 | H9: 6945006.9 | I9: 17805272 | J9: 17805272 | K9: 47.807616 | L9: 0.7461893 | M9: 0.75497339 | N9: 139.16 | O9: 70.56 | P9: 2783105.2 | Q9: 239171.21 | R9: 0 | S9: 0
A10: phased_ondemand | B10: base | C10: 40498712 | D10: 0.66990701 | E10: 47952580 | F10: 36238414 | G10: -9487088.5 | H10: 8619868.1 | I10: 16130411 | J10: 16080649 | K10: 29.79418 | L10: 0.72860101 | M10: 0.75571354 | N10: 161.7 | O10: 84.28 | P10: 4373229.9 | Q10: 0 | R10: 23 | S10: 3798557.3
A11: phased_ondemand | B11: upside | C11: 47700306 | D11: 0.96685452 | E11: 52744032 | F11: 40172457 | G11: -7029722.3 | H11: 5749408.9 | I11: 19000870 | J11: 18079217 | K11: 30.369355 | L11: 0.72940885 | M11: 0.76164933 | N11: 163.66 | O11: 84.28 | P11: 4871648.3 | Q11: 0 | R11: 25 | S11: 3944308
A12: phased_ondemand | B12: downside | C12: 29686367 | D12: 0.22407528 | E12: 40211019 | F12: 29627033 | G12: -12303541 | H12: 12063541 | I12: 12686738 | J12: 12686738 | K12: 20.648966 | L12: 0.72652001 | M12: 0.73678892 | N12: 160.72 | O12: 84.28 | P12: 3634520.2 | Q12: 0 | R12: 22 | S12: 3754853.1
A13: phased_commit | B13: base | C13: 40498712 | D13: 0.66990701 | E13: 47952580 | F13: 37048058 | G13: -8677444.5 | H13: 7810224.1 | I13: 16940055 | J13: 16800235 | K13: 32.678794 | L13: 0.74839602 | M13: 0.7725978 | N13: 161.7 | O13: 84.28 | P13: 3563585.9 | Q13: 42035.169 | R13: 23 | S13: 3798557.3
A14: phased_commit | B14: upside | C14: 47700306 | D14: 0.96685452 | E14: 52744032 | F14: 40979655 | G14: -6222524.2 | H14: 4942210.8 | I14: 19808068 | J14: 18721575 | K14: 32.650663 | L14: 0.7493189 | M14: 0.7769534 | N14: 163.66 | O14: 84.28 | P14: 4064450.2 | Q14: 26116.984 | R14: 25 | S14: 3944308
A15: phased_commit | B15: downside | C15: 29686367 | D15: 0.22407528 | E15: 40211019 | F15: 30407137 | G15: -11523437 | H15: 11283437 | I15: 13466842 | J15: 13466842 | K15: 23.282208 | L15: 0.7461893 | M15: 0.75618917 | N15: 160.72 | O15: 84.28 | P15: 2854416.1 | Q15: 177964.32 | R15: 22 | S15: 3754853.1
... A21: front_commit | B21: downside | C21: 30601464 | D21: 0.26180799 | E21: 40814965 | F21: 30873851 | G21: -14333241 | H21: 14064361 | I21: 10685919 | J21: 10685919 | K21: 16.895252 | L21: 0.7461893 | M21: 0.75643459 | N21: 167.58 | O21: 88.2 | P21: 2964470.1 | Q21: 136357.88 | R21: 29 | S21: 5591751.1

Sheet Actuals
A1: Actuals: P&L
A2: USD, monthly | B2: 2024-09 | C2: 2024-10 | D2: 2024-11 | E2: 2024-12 | F2: 2025-01 | G2: 2025-02 | H2: 2025-03 | I2: 2025-04 | J2: 2025-05 | K2: 2025-06 | L2: 2025-07 | M2: 2025-08 | N2: 2025-09 | O2: 2025-10 | P2: 2025-11 | Q2: 2025-12 | R2: 2026-01 | S2: 2026-02 | T2: 2026-03 | U2: 2026-04 | V2: 2026-05 | W2: 2026-06 | X2: 2026-07 | Y2: 2026-08
A3: Platform revenue | B3: 981087.54 | C3: 1005101.4 | D3: 1028451.5 | E3: 1058221.6 | F3: 1132259.3 | G3: 1156928.7 | H3: 1188773 | I3: 1213418.3 | J3: 1244815.3 | K3: 1279344.2 | L3: 1311167.6 | M3: 1338204.8 | N3: 1377821.6 | O3: 1413919.5 | P3: 1454201.3 | Q3: 1499311.7 | R3: 1612141.7 | S3: 1642915.6 | T3: 1679561.8 | U3: 1713674.2 | V3: 1753549.6 | W3: 1790911.9 | X3: 1820439.9 | Y3: 1855089.4
A4: Insights revenue | B4: 46887.791 | C4: 50241.447 | D4: 53663.045 | E4: 57489.502 | F4: 60996.656 | G4: 64792.621 | H4: 69049.882 | I4: 73098.061 | J4: 77648.099 | K4: 82525.814 | L4: 87370.617 | M4: 92158.861 | N4: 97963.036 | O4: 103731.41 | P4: 109933.91 | Q4: 116837.67 | R4: 121566.29 | S4: 127024.79 | T4: 133055.28 | U4: 139082.3 | V4: 145879.91 | W4: 152547.34 | X4: 158978.88 | Y4: 165916.92
A5: Revenue | B5: =B3+B4 | C5: =C3+C4 | D5: =D3+D4 | E5: =E3+E4 | F5: =F3+F4 | G5: =G3+G4 | H5: =H3+H4 | I5: =I3+I4 | ... Y5: =Y3+Y4
A6: Cloud hosting | B6: 88894.382 | C6: 93872.642 | D6: 95173.662 | E6: 96609.632 | F6: 100661.17 | G6: 102072.86 | H6: 103677.1 | I6: 108090.19 | J6: 109691.41 | K6: 111802.67 | L6: 115169.34 | M6: 116982 | N6: 123894.71 | O6: 125658.23 | P6: 125937.75 | Q6: 131699.79 | R6: 139519.28 | S6: 140607.98 | T6: 166479.2 | U6: 168149.6 | V6: 175878.46 | W6: 179584.58 | X6: 179693.64 | Y6: 188164.5
A7: Third-party software and data | B7: 30839.26 | C7: 31660.286 | D7: 32463.436 | E7: 33471.332 | F7: 35797.68 | G7: 36651.641 | H7: 37734.687 | I7: 38595.492 | J7: 39673.901 | K7: 40856.099 | L7: 41956.147 | M7: 42910.911 | N7: 44273.54 | O7: 45529.528 | P7: 46924.055 | Q7: 48484.481 | R7: 52011.239 | S7: 53098.213 | T7: 54378.511 | U7: 55582.696 | V7: 56982.884 | W7: 58303.776 | X7: 59382.564 | Y7: 60630.191
A8: Payment processing | B8: 15419.63 | C8: 15830.143 | D8: 16231.718 | E8: 16735.666 | F8: 17898.84 | G8: 18325.82 | H8: 18867.344 | I8: 19297.746 | J8: 19836.951 | K8: 20428.05 | L8: 20978.073 | M8: 21455.455 | N8: 22136.77 | O8: 22764.764 | P8: 23462.027 | Q8: 24242.24 | R8: 26005.62 | S8: 26549.106 | T8: 27189.255 | U8: 27791.348 | V8: 28491.442 | W8: 29151.888 | X8: 29691.282 | Y8: 30315.095
A9: Customer operations payroll | B9: 222370.56 | C9: 222370.56 | D9: 222370.56 | E9: 222370.56 | F9: 240095.71 | G9: 240095.71 | H9: 240095.71 | I9: 246775.54 | J9: 246775.54 | K9: 248489.18 | L9: 237684.54 | M9: 244781.41 | N9: 244781.41 | O9: 252735.9 | P9: 265489.5 | Q9: 265489.5 | R9: 274781.63 | S9: 274781.63 | T9: 283037.15 | U9: 283037.15 | V9: 283037.15 | W9: 282552.53 | X9: 282552.53 | Y9: 282552.53
A10: Customer operations recruiting | B10: 0 | C10: 0 | D10: 0 | E10: 0 | F10: 13642.261 | G10: 0 | H10: 0 | I10: 9551.7058 | J10: 0 | K10: 13381.939 | L10: 0 | M10: 10148.053 | N10: 0 | O10: 11374.386 | P10: 18236.795 | Q10: 0 | R10: 0 | S10: 0 | T10: 26770.03 | U10: 0 | V10: 0 | W10: 13524.443 | X10: 0 | Y10: 0
A11: Cost of revenue | B11: =B6+B7+B8+B9+B10 | C11: =C6+C7+C8+C9+C10 | D11: =D6+D7+D8+D9+D10 | E11: =E6+E7+E8+E9+E10 | F11: =F6+F7+F8+F9+F10 | G11: =G6+G7+G8+G9+G10 | H11: =H6+H7+H8+H9+H10 | I11: =I6+I7+I8+I9+I10 | ... Y11: =Y6+Y7+Y8+Y9+Y10
A12: Gross profit | B12: =B5-B11 | C12: =C5-C11 | D12: =D5-D11 | E12: =E5-E11 | F12: =F5-F11 | G12: =G5-G11 | H12: =H5-H11 | I12: =I5-I11 | ... Y12: =Y5-Y11
A13: Gross margin | B13: =IF(B5=0,0,B12/B5) | C13: =IF(C5=0,0,C12/C5) | D13: =IF(D5=0,0,D12/D5) | E13: =IF(E5=0,0,E12/E5) | F13: =IF(F5=0,0,F12/F5) | G13: =IF(G5=0,0,G12/G5) | H13: =IF(H5=0,0,H12/H5) | I13: =IF(I5=0,0,I12/I5) | ... Y13: =IF(Y5=0,0,Y12/Y5)
A14: R&D payroll | B14: 673876.11 | C14: 683643.19 | D14: 676675.92 | E14: 676675.92 | F14: 706370.87 | G14: 720011.33 | H14: 754184.7 | I14: 756900.63 | J14: 774196.61 | K14: 774196.61 | L14: 787402.77 | M14: 800933.62 | N14: 833018.62 | O14: 833018.62 | P14: 827647.36 | Q14: 827647.36 | R14: 856615.02 | S14: 856615.02 | T14: 862049.07 | U14: 885296.31 | V14: 910300.98 | W14: 890741.58 | X14: 925826.96 | Y14: 935879.88
A15: R&D recruiting | B15: 0 | C15: 13966.276 | D15: 12351.818 | E15: 0 | F15: 29113.757 | G15: 15504.431 | H15: 42618.522 | I15: 18602.984 | J15: 43278.389 | K15: 0 | L15: 18883.925 | M15: 19348.206 | N15: 39686.422 | O15: 0 | P15: 13927.866 | Q15: 0 | R15: 0 | S15: 0 | T15: 28759.315 | U15: 42383.073 | V15: 43841.115 | W15: 14438.192 | X15: 43898.195 | Y15: 14375.004
A16: R&D tooling | B16: 22950 | C16: 23400 | D16: 23400 | E16: 23400 | F16: 23850 | G16: 24300 | H16: 25650 | I16: 25650 | J16: 26550 | K16: 26550 | L16: 27000 | M16: 27450 | N16: 28800 | O16: 28800 | P16: 28800 | Q16: 28800 | R16: 28800 | S16: 28800 | T16: 29250 | U16: 30150 | V16: 31050 | W16: 30600 | X16: 31950 | Y16: 32400
A17: R&D contractors | B17: 55000 | C17: 55000 | D17: 55000 | E17: 55000 | F17: 55000 | G17: 55000 | H17: 55000 | I17: 55000 | J17: 55000 | K17: 55000 | L17: 55000 | M17: 55000 | N17: 55000 | O17: 55000 | P17: 55000 | Q17: 55000 | R17: 60000 | S17: 60000 | T17: 60000 | U17: 60000 | V17: 60000 | W17: 60000 | X17: 60000 | Y17: 60000
A18: R&D total | B18: =B14+B15+B16+B17 | C18: =C14+C15+C16+C17 | D18: =D14+D15+D16+D17 | E18: =E14+E15+E16+E17 | F18: =F14+F15+F16+F17 | G18: =G14+G15+G16+G17 | H18: =H14+H15+H16+H17 | I18: =I14+I15+I16+I17 | ... Y18: =Y14+Y15+Y16+Y17
A19: Sales and marketing payroll | B19: 206685.85 | C19: 206685.85 | D19: 218341.68 | E19: 218341.68 | F19: 232797.7 | G19: 244451.59 | H19: 244451.59 | I19: 255750.61 | J19: 247571.39 | K19: 253299.08 | L19: 288526.12 | M19: 281712.06 | N19: 288550.23 | O19: 306993.18 | P19: 306993.18 | Q19: 306993.18 | R19: 327723.15 | S19: 334190.58 | T19: 306855.27 | U19: 306855.27 | V19: 320140.53 | W19: 320140.53 | X19: 320140.53 | Y19: 320140.53
A20: Sales and marketing recruiting | B20: 0 | C20: 0 | D20: 17126.939 | E20: 0 | F20: 10012.488 | G20: 17124.094 | H20: 0 | I20: 16602.643 | J20: 0 | K20: 18243.62 | L20: 51762.18 | M20: 0 | N20: 10047.915 | O20: 27099.843 | P20: 0 | Q20: 0 | R20: 34134.999 | S20: 9503.1718 | T20: 0 | U20: 0 | V20: 18229.508 | W20: 0 | X20: 0 | Y20: 0
A21: Sales commission | B21: 38017.948 | C21: 38371.493 | D21: 38874.272 | E21: 46694.134 | F21: 36787.45 | G21: 41221.06 | H21: 49900.673 | I21: 41803.745 | J21: 49890.48 | K21: 54306.455 | L21: 51512.004 | M21: 46229.702 | N21: 61485.318 | O21: 58014.99 | P21: 63340.661 | Q21: 69546.983 | R21: 48737.061 | S21: 58264.46 | T21: 67352.568 | U21: 63305.941 | V21: 70130.115 | W21: 68101.655 | X21: 56649.129 | Y21: 62767.852
A22: Marketing programmes | B22: 224000 | C22: 224000 | D22: 224000 | E22: 280000 | F22: 196000 | G22: 224000 | H22: 280000 | I22: 224000 | J22: 280000 | K22: 308000 | L22: 280000 | M22: 252000 | N22: 364000 | O22: 336000 | P22: 364000 | Q22: 420000 | R22: 276300 | S22: 337700 | T22: 399100 | U22: 368400 | V22: 549800 | W22: 399100 | X22: 337700 | Y22: 368400
A23: Sales and marketing total | B23: =B19+B20+B21+B22 | C23: =C19+C20+C21+C22 | D23: =D19+D20+D21+D22 | E23: =E19+E20+E21+E22 | F23: =F19+F20+F21+F22 | G23: =G19+G20+G21+G22 | H23: =H19+H20+H21+H22 | I23: =I19+I20+I21+I22 | ... Y23: =Y19+Y20+Y21+Y22
A24: G&A payroll | B24: 221317.18 | C24: 221317.18 | D24: 221317.18 | E24: 221317.18 | F24: 229063.28 | G24: 229063.28 | H24: 229063.28 | I24: 229063.28 | J24: 218412.6 | K24: 218412.6 | L24: 218412.6 | M24: 218412.6 | N24: 218412.6 | O24: 228002.69 | P24: 228002.69 | Q24: 236914.49 | R24: 245206.49 | S24: 245206.49 | T24: 254910.49 | U24: 254910.49 | V24: 254910.49 | W24: 244028.04 | X24: 244028.04 | Y24: 252881.29
A25: G&A recruiting | B25: 0 | C25: 0 | D25: 0 | E25: 0 | F25: 0 | G25: 0 | H25: 0 | I25: 0 | J25: 0 | K25: 0 | L25: 0 | M25: 0 | N25: 0 | O25: 13713.186 | P25: 0 | Q25: 12743.278 | R25: 0 | S25: 0 | T25: 13876.07 | U25: 0 | V25: 0 | W25: 0 | X25: 0 | Y25: 12659.558
A26: Rent | B26: 50600 | C26: 51050 | D26: 51700 | E26: 51700 | F26: 53150 | G26: 54250 | H26: 55900 | I26: 56850 | J26: 56950 | K26: 57000 | L26: 58950 | M26: 59350 | N26: 61500 | O26: 63400 | P26: 63850 | Q26: 64300 | R26: 64800 | S26: 65300 | T26: 65550 | U26: 66750 | V26: 68300 | W26: 67450 | X26: 69100 | Y26: 70000
A27: Software seats | B27: 18720 | C27: 18900 | D27: 19080 | E27: 19080 | F27: 19620 | G27: 19980 | H27: 20520 | I27: 20880 | J27: 20880 | K27: 20880 | L27: 21600 | M27: 21780 | N27: 22500 | O27: 23220 | P27: 23400 | Q27: 23580 | R27: 23760 | S27: 23940 | T27: 24120 | U27: 24480 | V27: 25020 | W27: 24660 | X27: 25200 | Y27: 25560
A28: Fixed G&A | B28: 72000 | C28: 72000 | D28: 72000 | E28: 72000 | F28: 72000 | G28: 72000 | H28: 72000 | I28: 72000 | J28: 72000 | K28: 72000 | L28: 72000 | M28: 72000 | N28: 72000 | O28: 72000 | P28: 72000 | Q28: 72000 | R28: 75000 | S28: 75000 | T28: 75000 | U28: 75000 | V28: 75000 | W28: 75000 | X28: 75000 | Y28: 75000
A29: G&A total | B29: =B24+B25+B26+B27+B28 | C29: =C24+C25+C26+C27+C28 | D29: =D24+D25+D26+D27+D28 | E29: =E24+E25+E26+E27+E28 | F29: =F24+F25+F26+F27+F28 | G29: =G24+G25+G26+G27+G28 | H29: =H24+H25+H26+H27+H28 | I29: =I24+I25+I26+I27+I28 | ... Y29: =Y24+Y25+Y26+Y27+Y28
A30: Operating expenses | B30: =B18+B23+B29 | C30: =C18+C23+C29 | D30: =D18+D23+D29 | E30: =E18+E23+E29 | F30: =F18+F23+F29 | G30: =G18+G23+G29 | H30: =H18+H23+H29 | I30: =I18+I23+I29 | ... Y30: =Y18+Y23+Y29
A31: EBITDA | B31: =B12-B30 | C31: =C12-C30 | D31: =D12-D30 | E31: =E12-E30 | F31: =F12-F30 | G31: =G12-G30 | H31: =H12-H30 | I31: =I12-I30 | ... Y31: =Y12-Y30
A32: EBITDA margin | B32: =IF(B5=0,0,B31/B5) | C32: =IF(C5=0,0,C31/C5) | D32: =IF(D5=0,0,D31/D5) | E32: =IF(E5=0,0,E31/E5) | F32: =IF(F5=0,0,F31/F5) | G32: =IF(G5=0,0,G31/G5) | H32: =IF(H5=0,0,H31/H5) | I32: =IF(I5=0,0,I31/I5) | ... Y32: =IF(Y5=0,0,Y31/Y5)
A33: FTE total | B33: 104 | C33: 105 | D33: 106 | E33: 106 | F33: 109 | G33: 111 | H33: 114 | I33: 116 | J33: 116 | K33: 116 | L33: 120 | M33: 121 | N33: 125 | O33: 129 | P33: 130 | Q33: 131 | R33: 132 | S33: 133 | T33: 134 | U33: 136 | V33: 139 | W33: 137 | X33: 140 | Y33: 142
A34: FTE customer operations | B34: 22 | C34: 22 | D34: 22 | E34: 22 | F34: 23 | G34: 23 | H34: 23 | I34: 24 | J34: 24 | K34: 24 | L34: 23 | M34: 24 | N34: 24 | O34: 25 | P34: 26 | Q34: 26 | R34: 26 | S34: 26 | T34: 27 | U34: 27 | V34: 27 | W34: 27 | X34: 27 | Y34: 27
A35: FTE R&D | B35: 51 | C35: 52 | D35: 52 | E35: 52 | F35: 53 | G35: 54 | H35: 57 | I35: 57 | J35: 59 | K35: 59 | L35: 60 | M35: 61 | N35: 64 | O35: 64 | P35: 64 | Q35: 64 | R35: 64 | S35: 64 | T35: 65 | U35: 67 | V35: 69 | W35: 68 | X35: 71 | Y35: 72
A36: FTE sales and marketing | B36: 18 | C36: 18 | D36: 19 | E36: 19 | F36: 20 | G36: 21 | H36: 21 | I36: 22 | J36: 21 | K36: 21 | L36: 25 | M36: 24 | N36: 25 | O36: 27 | P36: 27 | Q36: 27 | R36: 28 | S36: 29 | T36: 27 | U36: 27 | V36: 28 | W36: 28 | X36: 28 | Y36: 28
A37: FTE G&A | B37: 13 | C37: 13 | D37: 13 | E37: 13 | F37: 13 | G37: 13 | H37: 13 | I37: 13 | J37: 12 | K37: 12 | L37: 12 | M37: 12 | N37: 12 | O37: 13 | P37: 13 | Q37: 14 | R37: 14 | S37: 14 | T37: 15 | U37: 15 | V37: 15 | W37: 14 | X37: 14 | Y37: 15
A38: Total ARR (closing) | B38: 12335704 | C38: 12664114 | D38: 12985374 | E38: 13388533 | F38: 14319072 | G38: 14660656 | H38: 15093875 | I38: 15438197 | J38: 15869561 | K38: 16342440 | L38: 16782459 | M38: 17164364 | N38: 17709416 | O38: 18211811 | P38: 18769622 | Q38: 19393792 | R38: 20804496 | S38: 21239285 | T38: 21751404 | U38: 22233078 | V38: 22793154 | W38: 23321510 | X38: 23753026 | Y38: 24252076
A39: Shaded yellow: values from the model. Shaded blue: Excel formulas.
A41: Actuals: ARR roll-forward
...

Sheet Budget FY2026
A1: Budget FY2026: P&L
A2: USD, monthly | B2: 2026-01 | C2: 2026-02 | D2: 2026-03 | E2: 2026-04 | F2: 2026-05 | G2: 2026-06 | H2: 2026-07 | I2: 2026-08 | J2: 2026-09 | K2: 2026-10 | L2: 2026-11 | M2: 2026-12
A3: Platform revenue | B3: 1614950.5 | C3: 1660358.5 | D3: 1714652.2 | E3: 1763407.2 | F3: 1816411.8 | G3: 1874614.7 | H3: 1919980.4 | I3: 1965383.6 | J3: 2021133 | K3: 2076928.5 | L3: 2130193.3 | M3: 2193810.6
A4: Insights revenue | B4: 123404.15 | C4: 130574.92 | D4: 138757.38 | E4: 146734.36 | F4: 155372.69 | G4: 164804.51 | H4: 173285.45 | I4: 182028.4 | J4: 192132.35 | K4: 202567.4 | L4: 213046.87 | M4: 225055.15
A5: Revenue | B5: =B3+B4 | C5: =C3+C4 | D5: =D3+D4 | E5: =E3+E4 | F5: =F3+F4 | G5: =G3+G4 | H5: =H3+H4 | I5: =I3+I4 | ... M5: =M3+M4
A6: Cloud hosting | B6: 139018.65 | C6: 142927.85 | D6: 147536.93 | E6: 151773.61 | F6: 156375 | G6: 161424.06 | H6: 165507.83 | I6: 169624.24 | J6: 174607.9 | K6: 179636.34 | L6: 184494 | M6: 190258.07
A7: Third-party software and data | B7: 52150.641 | C7: 53728.003 | D7: 55602.286 | E7: 57304.246 | F7: 59153.536 | G7: 61182.576 | H7: 62797.974 | I7: 64422.361 | J7: 66397.96 | K7: 68384.878 | L7: 70297.205 | M7: 72565.974
A8: Payment processing | B8: 26075.32 | C8: 26864.001 | D8: 27801.143 | E8: 28652.123 | F8: 29576.768 | G8: 30591.288 | H8: 31398.987 | I8: 32211.181 | J8: 33198.98 | K8: 34192.439 | L8: 35148.603 | M8: 36282.987
A9: Customer operations payroll | B9: 269286 | C9: 269286 | D9: 288569.46 | E9: 288569.46 | F9: 288569.46 | G9: 288569.46 | H9: 288569.46 | I9: 288569.46 | J9: 288569.46 | K9: 288569.46 | L9: 288569.46 | M9: 288569.46
A10: Customer operations recruiting | B10: 0 | C10: 0 | D10: 27000 | E10: 0 | F10: 0 | G10: 0 | H10: 0 | I10: 0 | J10: 0 | K10: 0 | L10: 0 | M10: 0
A11: Cost of revenue | B11: =B6+B7+B8+B9+B10 | C11: =C6+C7+C8+C9+C10 | D11: =D6+D7+D8+D9+D10 | E11: =E6+E7+E8+E9+E10 | F11: =F6+F7+F8+F9+F10 | G11: =G6+G7+G8+G9+G10 | H11: =H6+H7+H8+H9+H10 | I11: =I6+I7+I8+I9+I10 | ... M11: =M6+M7+M8+M9+M10
A12: Gross profit | B12: =B5-B11 | C12: =C5-C11 | D12: =D5-D11 | E12: =E5-E11 | F12: =F5-F11 | G12: =G5-G11 | H12: =H5-H11 | I12: =I5-I11 | ... M12: =M5-M11
A13: Gross margin | B13: =IF(B5=0,0,B12/B5) | C13: =IF(C5=0,0,C12/C5) | D13: =IF(D5=0,0,D12/D5) | E13: =IF(E5=0,0,E12/E5) | F13: =IF(F5=0,0,F12/F5) | G13: =IF(G5=0,0,G12/G5) | H13: =IF(H5=0,0,H12/H5) | I13: =IF(I5=0,0,I12/I5) | ... M13: =IF(M5=0,0,M12/M5)
A14: R&D payroll | B14: 868781.29 | C14: 925520.35 | D14: 950092.54 | E14: 950092.54 | F14: 950092.54 | G14: 950092.54 | H14: 950092.54 | I14: 950092.54 | J14: 950092.54 | K14: 950092.54 | L14: 950092.54 | M14: 950092.54
A15: R&D recruiting | B15: 42750 | C15: 73500 | D15: 28500 | E15: 0 | F15: 0 | G15: 0 | H15: 0 | I15: 0 | J15: 0 | K15: 0 | L15: 0 | M15: 0
A16: R&D tooling | B16: 29547 | C16: 31752 | D16: 32634 | E16: 32634 | F16: 32634 | G16: 32634 | H16: 32634 | I16: 32634 | J16: 32634 | K16: 32634 | L16: 32634 | M16: 32634
A17: R&D contractors | B17: 60000 | C17: 60000 | D17: 60000 | E17: 60000 | F17: 60000 | G17: 60000 | H17: 60000 | I17: 60000 | J17: 60000 | K17: 60000 | L17: 60000 | M17: 60000
A18: R&D total | B18: =B14+B15+B16+B17 | C18: =C14+C15+C16+C17 | D18: =D14+D15+D16+D17 | E18: =E14+E15+E16+E17 | F18: =F14+F15+F16+F17 | G18: =G14+G15+G16+G17 | H18: =H14+H15+H16+H17 | I18: =I14+I15+I16+I17 | ... M18: =M14+M15+M16+M17
A19: Sales and marketing payroll | B19: 333392.35 | C19: 339895.06 | D19: 339895.06 | E19: 352750.7 | F19: 352750.7 | G19: 352750.7 | H19: 352750.7 | I19: 352750.7 | J19: 352750.7 | K19: 352750.7 | L19: 352750.7 | M19: 352750.7
A20: Sales and marketing recruiting | B20: 33000 | C20: 9750 | D20: 0 | E20: 18000 | F20: 0 | G20: 0 | H20: 0 | I20: 0 | J20: 0 | K20: 0 | L20: 0 | M20: 0
A21: Sales commission | B21: 64535.604 | C21: 71430.283 | D21: 82569.437 | E21: 76492.576 | F21: 82103.649 | G21: 88897.453 | H21: 74103.373 | I21: 74624.414 | J21: 87515.938 | K21: 88156.24 | L21: 85704.561 | M21: 98686.377
A22: Marketing programmes | B22: 353430 | C22: 395010 | D22: 474320 | E22: 424270 | F22: 462000 | G22: 508200 | H22: 392700 | I22: 392700 | J22: 485100 | K22: 485100 | L22: 462000 | M22: 554400
A23: Sales and marketing total | B23: =B19+B20+B21+B22 | C23: =C19+C20+C21+C22 | D23: =D19+D20+D21+D22 | E23: =E19+E20+E21+E22 | F23: =F19+F20+F21+F22 | G23: =G19+G20+G21+G22 | H23: =H19+H20+H21+H22 | I23: =I19+I20+I21+I22 | ... M23: =M19+M20+M21+M22
A24: G&A payroll | B24: 240302.36 | C24: 249554.54 | D24: 249554.54 | E24: 249554.54 | F24: 249554.54 | G24: 249554.54 | H24: 249554.54 | I24: 249554.54 | J24: 249554.54 | K24: 249554.54 | L24: 249554.54 | M24: 249554.54
A25: G&A recruiting | B25: 0 | C25: 13500 | D25: 0 | E25: 0 | F25: 0 | G25: 0 | H25: 0 | I25: 0 | J25: 0 | K25: 0 | L25: 0 | M25: 0
A26: Rent | B26: 65317 | C26: 68894 | D26: 71050 | E26: 71540 | F26: 71540 | G26: 71540 | H26: 71540 | I26: 71540 | J26: 71540 | K26: 71540 | L26: 71540 | M26: 71540
A27: Software seats | B27: 23990.4 | C27: 25225.2 | D27: 25930.8 | E27: 26107.2 | F27: 26107.2 | G27: 26107.2 | H27: 26107.2 | I27: 26107.2 | J27: 26107.2 | K27: 26107.2 | L27: 26107.2 | M27: 26107.2
A28: Fixed G&A | B28: 75000 | C28: 75000 | D28: 75000 | E28: 75000 | F28: 75000 | G28: 75000 | H28: 75000 | I28: 75000 | J28: 75000 | K28: 75000 | L28: 75000 | M28: 75000
A29: G&A total | B29: =B24+B25+B26+B27+B28 | C29: =C24+C25+C26+C27+C28 | D29: =D24+D25+D26+D27+D28 | E29: =E24+E25+E26+E27+E28 | F29: =F24+F25+F26+F27+F28 | G29: =G24+G25+G26+G27+G28 | H29: =H24+H25+H26+H27+H28 | I29: =I24+I25+I26+I27+I28 | ... M29: =M24+M25+M26+M27+M28
A30: Operating expenses | B30: =B18+B23+B29 | C30: =C18+C23+C29 | D30: =D18+D23+D29 | E30: =E18+E23+E29 | F30: =F18+F23+F29 | G30: =G18+G23+G29 | H30: =H18+H23+H29 | I30: =I18+I23+I29 | ... M30: =M18+M23+M29
A31: EBITDA | B31: =B12-B30 | C31: =C12-C30 | D31: =D12-D30 | E31: =E12-E30 | F31: =F12-F30 | G31: =G12-G30 | H31: =H12-H30 | I31: =I12-I30 | ... M31: =M12-M30
A32: EBITDA margin | B32: =IF(B5=0,0,B31/B5) | C32: =IF(C5=0,0,C31/C5) | D32: =IF(D5=0,0,D31/D5) | E32: =IF(E5=0,0,E31/E5) | F32: =IF(F5=0,0,F31/F5) | G32: =IF(G5=0,0,G31/G5) | H32: =IF(H5=0,0,H31/H5) | I32: =IF(I5=0,0,I31/I5) | ... M32: =IF(M5=0,0,M31/M5)
A33: FTE total | B33: 133.28 | C33: 140.14 | D33: 144.06 | E33: 145.04 | F33: 145.04 | G33: 145.04 | H33: 145.04 | I33: 145.04 | J33: 145.04 | K33: 145.04 | L33: 145.04 | M33: 145.04
A34: FTE customer operations | B34: 25.48 | C34: 25.48 | D34: 27.44 | E34: 27.44 | F34: 27.44 | G34: 27.44 | H34: 27.44 | I34: 27.44 | J34: 27.44 | K34: 27.44 | L34: 27.44 | M34: 27.44
A35: FTE R&D | B35: 65.66 | C35: 70.56 | D35: 72.52 | E35: 72.52 | F35: 72.52 | G35: 72.52 | H35: 72.52 | I35: 72.52 | J35: 72.52 | K35: 72.52 | L35: 72.52 | M35: 72.52
A36: FTE sales and marketing | B36: 28.42 | C36: 29.4 | D36: 29.4 | E36: 30.38 | F36: 30.38 | G36: 30.38 | H36: 30.38 | I36: 30.38 | J36: 30.38 | K36: 30.38 | L36: 30.38 | M36: 30.38
A37: FTE G&A | B37: 13.72 | C37: 14.7 | D37: 14.7 | E37: 14.7 | F37: 14.7 | G37: 14.7 | H37: 14.7 | I37: 14.7 | J37: 14.7 | K37: 14.7 | L37: 14.7 | M37: 14.7
A38: Total ARR (closing) | B38: 20860256 | C38: 21491201 | D38: 22240915 | E38: 22921698 | F38: 23661414 | G38: 24473030 | H38: 25119190 | I38: 25768945 | J38: 26559184 | K38: 27353951 | L38: 28118882 | M38: 29026389
A39: Shaded yellow: values from the model. Shaded blue: Excel formulas.
A41: Budget FY2026: ARR roll-forward
...

Sheet Bridge YTD
A1: January to August 2026, actual versus budget. impact = effect on EBITDA (favorable positive). Components sum to the EBITDA variance.
A3: line_label | B3: component | C3: budget | D3: actual | E3: impact | F3: material
A4: Platform revenue | B4: volume | C4: 14329759 | D4: 13868284 | E4: -560502.28 | F4: TRUE
A5: Platform revenue | B5: price | C5: 14329759 | D5: 13868284 | E5: 99027.443 | F5: FALSE
A6: Insights revenue | B6: volume | C6: 1214961.9 | D6: 1144051.7 | E6: -70910.158 | F6: TRUE
A7: Insights revenue | B7: price | C7: 1214961.9 | D7: 1144051.7 | E7: 1.1340982e-10 | F7: FALSE
A8: Cloud hosting | B8: usage | C8: 1234188.2 | D8: 1338077.3 | E8: -103889.09 | F8: TRUE
A9: Cloud hosting | B9: rate | C9: 1234188.2 | D9: 1338077.3 | E9: -7.7886588e-11 | F9: FALSE
A10: Cloud hosting | B10: fixed | C10: 1234188.2 | D10: 1338077.3 | E10: 0 | F10: FALSE
A11: Customer operations payroll | B11: headcount | C11: 2269988.8 | D11: 2246332.3 | E11: 16771.977 | F11: FALSE
A12: Customer operations payroll | B12: rate | C12: 2269988.8 | D12: 2246332.3 | E12: 6884.4833 | F12: FALSE
A13: R&D payroll | B13: headcount | C13: 7494856.9 | D13: 7123324.8 | E13: 410908.1 | F13: TRUE
A14: R&D payroll | B14: rate | C14: 7494856.9 | D14: 7123324.8 | E14: -39376.046 | F14: FALSE
A15: Sales and marketing payroll | B15: headcount | C15: 2776935.9 | D15: 2556186.4 | E15: 187083.45 | F15: TRUE
... A32: Fixed G&A | B32: spend | C32: 600000 | D32: 600000 | E32: 0 | F32: FALSE

Sheet Plan base
A1: Plan base: P&L
A2: USD, monthly | B2: 2026-09 | C2: 2026-10 | D2: 2026-11 | E2: 2026-12 | F2: 2027-01 | G2: 2027-02 | H2: 2027-03 | I2: 2027-04 | J2: 2027-05 | K2: 2027-06 | L2: 2027-07 | M2: 2027-08 | N2: 2027-09 | O2: 2027-10 | P2: 2027-11 | Q2: 2027-12 | R2: 2028-01 | S2: 2028-02
A3: Platform revenue | B3: 1896810.2 | C3: 1938531.1 | D3: 1978974.7 | E3: 2028358.5 | F3: 2169336.7 | G3: 2213218 | H3: 2265667 | I3: 2312379.4 | J3: 2363785.4 | K3: 2421151.5 | L3: 2466113.2 | M3: 2511708 | N3: 2568031.1 | O3: 2624354.2 | P3: 2677995.3 | Q3: 2742364.5 | R3: 2930173.5 | S3: 2983680.4
A4: Insights revenue | B4: 174264.46 | C4: 182865.14 | D4: 191583.63 | E4: 201560.34 | F4: 210490.55 | G4: 220156.57 | H4: 231101.58 | I4: 242874.19 | J4: 255595.04 | K4: 269489.52 | L4: 282165.2 | M4: 295289.61 | N4: 310324.12 | O4: 325820.1 | P4: 341374.79 | Q4: 359072.68 | R4: 374707.05 | S4: 391212.27
A5: Revenue | B5: =B3+B4 | C5: =C3+C4 | D5: =D3+D4 | E5: =E3+E4 | F5: =F3+F4 | G5: =G3+G4 | H5: =H3+H4 | I5: =I3+I4 | ... S5: =S3+S4
A6: Cloud hosting | B6: 150990.8 | C6: 154738.82 | D6: 158423.03 | E6: 162807.69 | F6: 166339.77 | G6: 171538.51 | H6: 177682.32 | I6: 184045.32 | J6: 190948.11 | K6: 198540.35 | L6: 204896.54 | M6: 211369.16 | N6: 219062.92 | O6: 226828 | P6: 234360.44 | Q6: 243179.31 | R6: 250217.82 | S6: 257616.99
A7: Third-party software and data | B7: 62132.241 | C7: 63641.886 | D7: 65116.749 | E7: 66897.565 | F7: 71394.817 | G7: 73001.238 | H7: 74903.059 | I7: 76657.609 | J7: 78581.414 | K7: 80719.232 | L7: 82448.351 | M7: 84209.93 | N7: 86350.658 | O7: 88505.23 | P7: 90581.101 | Q7: 93043.115 | R7: 99146.417 | S7: 101246.78
A8: Payment processing | B8: 31066.121 | C8: 31820.943 | D8: 32558.375 | E8: 33448.783 | F8: 35697.408 | G8: 36500.619 | H8: 37451.529 | I8: 38328.805 | J8: 39290.707 | K8: 40359.616 | L8: 41224.175 | M8: 42104.965 | N8: 43175.329 | O8: 44252.615 | P8: 45290.551 | Q8: 46521.558 | R8: 49573.208 | S8: 50623.39
A9: Customer operations payroll | B9: 276901.48 | C9: 276901.48 | D9: 276901.48 | E9: 276901.48 | F9: 286593.03 | G9: 286593.03 | H9: 286593.03 | I9: 286593.03 | J9: 286593.03 | K9: 286593.03 | L9: 286593.03 | M9: 286593.03 | N9: 286593.03 | O9: 286593.03 | P9: 286593.03 | Q9: 296234.76 | R9: 306602.98 | S9: 306602.98
A10: Customer operations recruiting | B10: 0 | C10: 0 | D10: 0 | E10: 0 | F10: 0 | G10: 0 | H10: 0 | I10: 0 | J10: 0 | K10: 0 | L10: 0 | M10: 0 | N10: 0 | O10: 0 | P10: 0 | Q10: 13500 | R10: 0 | S10: 0
A11: Cost of revenue | B11: =B6+B7+B8+B9+B10 | C11: =C6+C7+C8+C9+C10 | D11: =D6+D7+D8+D9+D10 | E11: =E6+E7+E8+E9+E10 | F11: =F6+F7+F8+F9+F10 | G11: =G6+G7+G8+G9+G10 | H11: =H6+H7+H8+H9+H10 | I11: =I6+I7+I8+I9+I10 | ... S11: =S6+S7+S8+S9+S10
A12: Gross profit | B12: =B5-B11 | C12: =C5-C11 | D12: =D5-D11 | E12: =E5-E11 | F12: =F5-F11 | G12: =G5-G11 | H12: =H5-H11 | I12: =I5-I11 | ... S12: =S5-S11
A13: Gross margin | B13: =IF(B5=0,0,B12/B5) | C13: =IF(C5=0,0,C12/C5) | D13: =IF(D5=0,0,D12/D5) | E13: =IF(E5=0,0,E12/E5) | F13: =IF(F5=0,0,F12/F5) | G13: =IF(G5=0,0,G12/G5) | H13: =IF(H5=0,0,H12/H5) | I13: =IF(I5=0,0,I12/I5) | ... S13: =IF(S5=0,0,S12/S5)
A14: R&D payroll | B14: 917162.28 | C14: 942862.78 | D14: 983087.54 | E14: 983087.54 | F14: 1054404 | G14: 1067983.4 | H14: 1087515.8 | I14: 1087515.8 | J14: 1108208.2 | K14: 1108208.2 | L14: 1108208.2 | M14: 1108208.2 | N14: 1108208.2 | O14: 1108208.2 | P14: 1108208.2 | Q14: 1108208.2 | R14: 1146995.4 | S14: 1146995.4
A15: R&D recruiting | B15: 0 | C15: 37500 | D15: 52500 | E15: 0 | F15: 46500 | G15: 15750 | H15: 28500 | I15: 0 | J15: 24000 | K15: 0 | L15: 0 | M15: 0 | N15: 0 | O15: 0 | P15: 0 | Q15: 0 | R15: 0 | S15: 0
A16: R&D tooling | B16: 31752 | C16: 32634 | D16: 34398 | E16: 34398 | F16: 35721 | G16: 36162 | H16: 37044 | I16: 37044 | J16: 37926 | K16: 37926 | L16: 37926 | M16: 37926 | N16: 37926 | O16: 37926 | P16: 37926 | Q16: 37926 | R16: 37926 | S16: 37926
A17: R&D contractors | B17: 60000 | C17: 60000 | D17: 60000 | E17: 60000 | F17: 60000 | G17: 60000 | H17: 60000 | I17: 60000 | J17: 60000 | K17: 60000 | L17: 60000 | M17: 60000 | N17: 60000 | O17: 60000 | P17: 60000 | Q17: 60000 | R17: 60000 | S17: 60000
A18: R&D total | B18: =B14+B15+B16+B17 | C18: =C14+C15+C16+C17 | D18: =D14+D15+D16+D17 | E18: =E14+E15+E16+E17 | F18: =F14+F15+F16+F17 | G18: =G14+G15+G16+G17 | H18: =H14+H15+H16+H17 | I18: =I14+I15+I16+I17 | ... S18: =S14+S15+S16+S17
A19: Sales and marketing payroll | B19: 313737.72 | C19: 324742.3 | D19: 324742.3 | E19: 324742.3 | F19: 371122.87 | G19: 383978.51 | H19: 383978.51 | I19: 394983.09 | J19: 394983.09 | K19: 394983.09 | L19: 394983.09 | M19: 394983.09 | N19: 394983.09 | O19: 394983.09 | P19: 394983.09 | Q19: 394983.09 | R19: 408807.5 | S19: 408807.5
A20: Sales and marketing recruiting | B20: 0 | C20: 16500 | D20: 0 | E20: 0 | F20: 52500 | G20: 18000 | H20: 0 | I20: 16500 | J20: 0 | K20: 0 | L20: 0 | M20: 0 | N20: 0 | O20: 0 | P20: 0 | Q20: 0 | R20: 0 | S20: 0
A21: Sales commission | B21: 69524.73 | C21: 69962.379 | D21: 68867.426 | E21: 80019.884 | F21: 68749.661 | G21: 75413.813 | H21: 86155.324 | I21: 79821.577 | J21: 85943.896 | K21: 93635.279 | L21: 79351.659 | M21: 80583.218 | N21: 93935.354 | O21: 94526.179 | P21: 91898.542 | Q21: 105335.08 | R21: 89596.154 | S21: 94945.643
A22: Marketing programmes | B22: 396900 | C22: 396900 | D22: 384750 | E22: 469800 | F22: 358425 | G22: 397575 | H22: 475200 | I22: 423225 | J22: 465750 | K22: 519750 | L22: 407362.5 | M22: 413100 | N22: 510300 | O22: 510300 | P22: 486000 | Q22: 583200 | R22: 437400 | S22: 461700
A23: Sales and marketing total | B23: =B19+B20+B21+B22 | C23: =C19+C20+C21+C22 | D23: =D19+D20+D21+D22 | E23: =E19+E20+E21+E22 | F23: =F19+F20+F21+F22 | G23: =G19+G20+G21+G22 | H23: =H19+H20+H21+H22 | I23: =I19+I20+I21+I22 | ... S23: =S19+S20+S21+S22
A24: G&A payroll | B24: 247823.66 | C24: 247823.66 | D24: 247823.66 | E24: 247823.66 | F24: 265749.67 | G24: 265749.67 | H24: 265749.67 | I24: 265749.67 | J24: 265749.67 | K24: 265749.67 | L24: 265749.67 | M24: 265749.67 | N24: 265749.67 | O24: 265749.67 | P24: 265749.67 | Q24: 265749.67 | R24: 275050.91 | S24: 275050.91
A25: G&A recruiting | B25: 0 | C25: 0 | D25: 0 | E25: 0 | F25: 13500 | G25: 0 | H25: 0 | I25: 0 | J25: 0 | K25: 0 | L25: 0 | M25: 0 | N25: 0 | O25: 0 | P25: 0 | Q25: 0 | R25: 0 | S25: 0
A26: Rent | B26: 68600 | C26: 69972 | D26: 72030 | E26: 72030 | F26: 76048 | G26: 77126 | H26: 78008 | I26: 78498 | J26: 79674 | K26: 79674 | L26: 79674 | M26: 79674 | N26: 79674 | O26: 79674 | P26: 79674 | Q26: 80164 | R26: 80164 | S26: 80164
A27: Software seats | B27: 25048.8 | C27: 25578 | D27: 26283.6 | E27: 26283.6 | F27: 27694.8 | G27: 28047.6 | H27: 28400.4 | I27: 28576.8 | J27: 28929.6 | K27: 28929.6 | L27: 28929.6 | M27: 28929.6 | N27: 28929.6 | O27: 28929.6 | P27: 28929.6 | Q27: 29106 | R27: 29106 | S27: 29106
A28: Fixed G&A | B28: 75000 | C28: 75000 | D28: 75000 | E28: 75000 | F28: 75000 | G28: 75000 | H28: 75000 | I28: 75000 | J28: 75000 | K28: 75000 | L28: 75000 | M28: 75000 | N28: 75000 | O28: 75000 | P28: 75000 | Q28: 75000 | R28: 75000 | S28: 75000
A29: G&A total | B29: =B24+B25+B26+B27+B28 | C29: =C24+C25+C26+C27+C28 | D29: =D24+D25+D26+D27+D28 | E29: =E24+E25+E26+E27+E28 | F29: =F24+F25+F26+F27+F28 | G29: =G24+G25+G26+G27+G28 | H29: =H24+H25+H26+H27+H28 | I29: =I24+I25+I26+I27+I28 | ... S29: =S24+S25+S26+S27+S28
A30: Operating expenses | B30: =B18+B23+B29 | C30: =C18+C23+C29 | D30: =D18+D23+D29 | E30: =E18+E23+E29 | F30: =F18+F23+F29 | G30: =G18+G23+G29 | H30: =H18+H23+H29 | I30: =I18+I23+I29 | ... S30: =S18+S23+S29
A31: EBITDA | B31: =B12-B30 | C31: =C12-C30 | D31: =D12-D30 | E31: =E12-E30 | F31: =F12-F30 | G31: =G12-G30 | H31: =H12-H30 | I31: =I12-I30 | ... S31: =S12-S30
A32: EBITDA margin | B32: =IF(B5=0,0,B31/B5) | C32: =IF(C5=0,0,C31/C5) | D32: =IF(D5=0,0,D31/D5) | E32: =IF(E5=0,0,E31/E5) | F32: =IF(F5=0,0,F31/F5) | G32: =IF(G5=0,0,G31/G5) | H32: =IF(H5=0,0,H31/H5) | I32: =IF(I5=0,0,I31/I5) | ... S32: =IF(S5=0,0,S31/S5)
A33: FTE total | B33: 139.16 | C33: 142.1 | D33: 146.02 | E33: 146.02 | F33: 153.86 | G33: 155.82 | H33: 157.78 | I33: 158.76 | J33: 160.72 | K33: 160.72 | L33: 160.72 | M33: 160.72 | N33: 160.72 | O33: 160.72 | P33: 160.72 | Q33: 161.7 | R33: 161.7 | S33: 161.7
A34: FTE customer operations | B34: 26.46 | C34: 26.46 | D34: 26.46 | E34: 26.46 | F34: 26.46 | G34: 26.46 | H34: 26.46 | I34: 26.46 | J34: 26.46 | K34: 26.46 | L34: 26.46 | M34: 26.46 | N34: 26.46 | O34: 26.46 | P34: 26.46 | Q34: 27.44 | R34: 27.44 | S34: 27.44
A35: FTE R&D | B35: 70.56 | C35: 72.52 | D35: 76.44 | E35: 76.44 | F35: 79.38 | G35: 80.36 | H35: 82.32 | I35: 82.32 | J35: 84.28 | K35: 84.28 | L35: 84.28 | M35: 84.28 | N35: 84.28 | O35: 84.28 | P35: 84.28 | Q35: 84.28 | R35: 84.28 | S35: 84.28
A36: FTE sales and marketing | B36: 27.44 | C36: 28.42 | D36: 28.42 | E36: 28.42 | F36: 32.34 | G36: 33.32 | H36: 33.32 | I36: 34.3 | J36: 34.3 | K36: 34.3 | L36: 34.3 | M36: 34.3 | N36: 34.3 | O36: 34.3 | P36: 34.3 | Q36: 34.3 | R36: 34.3 | S36: 34.3
A37: FTE G&A | B37: 14.7 | C37: 14.7 | D37: 14.7 | E37: 14.7 | F37: 15.68 | G37: 15.68 | H37: 15.68 | I37: 15.68 | J37: 15.68 | K37: 15.68 | L37: 15.68 | M37: 15.68 | N37: 15.68 | O37: 15.68 | P37: 15.68 | Q37: 15.68 | R37: 15.68 | S37: 15.68
A38: Total ARR (closing) | B38: 24852896 | C38: 25456754 | D38: 26046700 | E38: 26759026 | F38: 28557927 | G38: 29200495 | H38: 29961224 | I38: 30663044 | J38: 31432566 | K38: 32287693 | L38: 32979340 | M38: 33683972 | N38: 34540263 | O38: 35402092 | P38: 36232441 | Q38: 37217246 | R38: 39658567 | S38: 40498712
A39: Shaded yellow: values from the model. Shaded blue: Excel formulas.
A41: Plan base: ARR roll-forward
...

Sheet Plan upside
A1: Plan upside: P&L
A2: USD, monthly | B2: 2026-09 | C2: 2026-10 | D2: 2026-11 | E2: 2026-12 | F2: 2027-01 | G2: 2027-02 | H2: 2027-03 | I2: 2027-04 | J2: 2027-05 | K2: 2027-06 | L2: 2027-07 | M2: 2027-08 | N2: 2027-09 | O2: 2027-10 | P2: 2027-11 | Q2: 2027-12 | R2: 2028-01 | S2: 2028-02
A3: Platform revenue | B3: 1910656.7 | C3: 1966361 | D3: 2020641.7 | E3: 2085983.1 | F3: 2286418.9 | G3: 2346712.2 | H3: 2417825.2 | I3: 2481968.6 | J3: 2552116.1 | K3: 2629860 | L3: 2692345.7 | M3: 2755774.3 | N3: 2832721.4 | O3: 2909858.2 | P3: 2983844.7 | Q3: 3071375.7 | R3: 3358285 | S3: 3434479.8
A4: Insights revenue | B4: 178411.47 | C4: 191495.49 | D4: 205006.64 | E4: 220430.55 | F4: 234797.76 | G4: 250426.91 | H4: 268092.09 | I4: 286911.72 | J4: 307390.69 | K4: 329890.73 | L4: 351069.55 | M4: 373257.06 | N4: 398593.85 | O4: 425045.4 | P4: 452034.26 | Q4: 482680.01 | R4: 510724.23 | S4: 540545.67
A5: Revenue | B5: =B3+B4 | C5: =C3+C4 | D5: =D3+D4 | E5: =E3+E4 | F5: =F3+F4 | G5: =G3+G4 | H5: =H3+H4 | I5: =I3+I4 | ... S5: =S3+S4
A6: Cloud hosting | B6: 152780.36 | C6: 158372.26 | D6: 163929.89 | E6: 171801.63 | F6: 179213.64 | G6: 187250.38 | H6: 196475.54 | I6: 205868.64 | J6: 216015.71 | K6: 227119.08 | L6: 236682.28 | M6: 246447.38 | N6: 257864.41 | O6: 269437.4 | P6: 280762.91 | Q6: 293850.07 | R6: 304634.12 | S6: 315944.52
A7: Third-party software and data | B7: 62672.045 | C7: 64735.694 | D7: 66769.449 | E7: 69192.41 | F7: 75636.501 | G7: 77914.173 | H7: 80577.519 | I7: 83066.41 | J7: 85785.205 | K7: 88792.521 | L7: 91302.458 | M7: 93870.942 | N7: 96939.456 | O7: 100047.11 | P7: 103076.37 | Q7: 106621.67 | R7: 116070.28 | S7: 119250.76
A8: Payment processing | B8: 31336.022 | C8: 32367.847 | D8: 33384.725 | E8: 34596.205 | F8: 37818.25 | G8: 38957.086 | H8: 40288.759 | I8: 41533.205 | J8: 42892.602 | K8: 44396.261 | L8: 45651.229 | M8: 46935.471 | N8: 48469.728 | O8: 50023.554 | P8: 51538.185 | Q8: 53310.836 | R8: 58035.138 | S8: 59625.382
A9: Customer operations payroll | B9: 276901.48 | C9: 276901.48 | D9: 276901.48 | E9: 276901.48 | F9: 286593.03 | G9: 286593.03 | H9: 286593.03 | I9: 286593.03 | J9: 286593.03 | K9: 286593.03 | L9: 296234.76 | M9: 296234.76 | N9: 296234.76 | O9: 305876.49 | P9: 305876.49 | Q9: 305876.49 | R9: 326223.9 | S9: 326223.9
A10: Customer operations recruiting | B10: 0 | C10: 0 | D10: 0 | E10: 0 | F10: 0 | G10: 0 | H10: 0 | I10: 0 | J10: 0 | K10: 0 | L10: 13500 | M10: 0 | N10: 0 | O10: 13500 | P10: 0 | Q10: 0 | R10: 13500 | S10: 0
A11: Cost of revenue | B11: =B6+B7+B8+B9+B10 | C11: =C6+C7+C8+C9+C10 | D11: =D6+D7+D8+D9+D10 | E11: =E6+E7+E8+E9+E10 | F11: =F6+F7+F8+F9+F10 | G11: =G6+G7+G8+G9+G10 | H11: =H6+H7+H8+H9+H10 | I11: =I6+I7+I8+I9+I10 | ... S11: =S6+S7+S8+S9+S10
A12: Gross profit | B12: =B5-B11 | C12: =C5-C11 | D12: =D5-D11 | E12: =E5-E11 | F12: =F5-F11 | G12: =G5-G11 | H12: =H5-H11 | I12: =I5-I11 | ... S12: =S5-S11
A13: Gross margin | B13: =IF(B5=0,0,B12/B5) | C13: =IF(C5=0,0,C12/C5) | D13: =IF(D5=0,0,D12/D5) | E13: =IF(E5=0,0,E12/E5) | F13: =IF(F5=0,0,F12/F5) | G13: =IF(G5=0,0,G12/G5) | H13: =IF(H5=0,0,H12/H5) | I13: =IF(I5=0,0,I12/I5) | ... S13: =IF(S5=0,0,S12/S5)
A14: R&D payroll | B14: 917162.28 | C14: 942862.78 | D14: 983087.54 | E14: 983087.54 | F14: 1054404 | G14: 1067983.4 | H14: 1087515.8 | I14: 1087515.8 | J14: 1108208.2 | K14: 1108208.2 | L14: 1108208.2 | M14: 1108208.2 | N14: 1108208.2 | O14: 1108208.2 | P14: 1108208.2 | Q14: 1108208.2 | R14: 1146995.4 | S14: 1146995.4
A15: R&D recruiting | B15: 0 | C15: 37500 | D15: 52500 | E15: 0 | F15: 46500 | G15: 15750 | H15: 28500 | I15: 0 | J15: 24000 | K15: 0 | L15: 0 | M15: 0 | N15: 0 | O15: 0 | P15: 0 | Q15: 0 | R15: 0 | S15: 0
A16: R&D tooling | B16: 31752 | C16: 32634 | D16: 34398 | E16: 34398 | F16: 35721 | G16: 36162 | H16: 37044 | I16: 37044 | J16: 37926 | K16: 37926 | L16: 37926 | M16: 37926 | N16: 37926 | O16: 37926 | P16: 37926 | Q16: 37926 | R16: 37926 | S16: 37926
A17: R&D contractors | B17: 60000 | C17: 60000 | D17: 60000 | E17: 60000 | F17: 60000 | G17: 60000 | H17: 60000 | I17: 60000 | J17: 60000 | K17: 60000 | L17: 60000 | M17: 60000 | N17: 60000 | O17: 60000 | P17: 60000 | Q17: 60000 | R17: 60000 | S17: 60000
A18: R&D total | B18: =B14+B15+B16+B17 | C18: =C14+C15+C16+C17 | D18: =D14+D15+D16+D17 | E18: =E14+E15+E16+E17 | F18: =F14+F15+F16+F17 | G18: =G14+G15+G16+G17 | H18: =H14+H15+H16+H17 | I18: =I14+I15+I16+I17 | ... S18: =S14+S15+S16+S17
A19: Sales and marketing payroll | B19: 313737.72 | C19: 324742.3 | D19: 324742.3 | E19: 324742.3 | F19: 371122.87 | G19: 383978.51 | H19: 383978.51 | I19: 394983.09 | J19: 394983.09 | K19: 394983.09 | L19: 394983.09 | M19: 394983.09 | N19: 394983.09 | O19: 394983.09 | P19: 394983.09 | Q19: 394983.09 | R19: 408807.5 | S19: 408807.5
A20: Sales and marketing recruiting | B20: 0 | C20: 16500 | D20: 0 | E20: 0 | F20: 52500 | G20: 18000 | H20: 0 | I20: 16500 | J20: 0 | K20: 0 | L20: 0 | M20: 0 | N20: 0 | O20: 0 | P20: 0 | Q20: 0 | R20: 0 | S20: 0
A21: Sales commission | B21: 82095.114 | C21: 82721.289 | D21: 81475.83 | E21: 95199.76 | F21: 82633.386 | G21: 91350.359 | H21: 104835.05 | I21: 97062.451 | J21: 104800.32 | K21: 114498.81 | L21: 96835.097 | M21: 98485.712 | N21: 115234.89 | O21: 116101.99 | P21: 112962.62 | Q21: 129830.77 | R21: 111816.36 | S21: 119338.68
A22: Marketing programmes | B22: 452760 | C22: 452760 | D22: 438900 | E22: 535920 | F22: 408870 | G22: 453530 | H22: 542080 | I22: 482790 | J22: 531300 | K22: 592900 | L22: 464695 | M22: 471240 | N22: 582120 | O22: 582120 | P22: 554400 | Q22: 665280 | R22: 498960 | S22: 526680
A23: Sales and marketing total | B23: =B19+B20+B21+B22 | C23: =C19+C20+C21+C22 | D23: =D19+D20+D21+D22 | E23: =E19+E20+E21+E22 | F23: =F19+F20+F21+F22 | G23: =G19+G20+G21+G22 | H23: =H19+H20+H21+H22 | I23: =I19+I20+I21+I22 | ... S23: =S19+S20+S21+S22
A24: G&A payroll | B24: 247823.66 | C24: 247823.66 | D24: 247823.66 | E24: 247823.66 | F24: 265749.67 | G24: 265749.67 | H24: 265749.67 | I24: 265749.67 | J24: 265749.67 | K24: 265749.67 | L24: 265749.67 | M24: 265749.67 | N24: 265749.67 | O24: 265749.67 | P24: 265749.67 | Q24: 265749.67 | R24: 275050.91 | S24: 275050.91
A25: G&A recruiting | B25: 0 | C25: 0 | D25: 0 | E25: 0 | F25: 13500 | G25: 0 | H25: 0 | I25: 0 | J25: 0 | K25: 0 | L25: 0 | M25: 0 | N25: 0 | O25: 0 | P25: 0 | Q25: 0 | R25: 0 | S25: 0
A26: Rent | B26: 68600 | C26: 69972 | D26: 72030 | E26: 72030 | F26: 76048 | G26: 77126 | H26: 78008 | I26: 78498 | J26: 79674 | K26: 79674 | L26: 80164 | M26: 80164 | N26: 80164 | O26: 80654 | P26: 80654 | Q26: 80654 | R26: 81144 | S26: 81144
A27: Software seats | B27: 25048.8 | C27: 25578 | D27: 26283.6 | E27: 26283.6 | F27: 27694.8 | G27: 28047.6 | H27: 28400.4 | I27: 28576.8 | J27: 28929.6 | K27: 28929.6 | L27: 29106 | M27: 29106 | N27: 29106 | O27: 29282.4 | P27: 29282.4 | Q27: 29282.4 | R27: 29458.8 | S27: 29458.8
A28: Fixed G&A | B28: 75000 | C28: 75000 | D28: 75000 | E28: 75000 | F28: 75000 | G28: 75000 | H28: 75000 | I28: 75000 | J28: 75000 | K28: 75000 | L28: 75000 | M28: 75000 | N28: 75000 | O28: 75000 | P28: 75000 | Q28: 75000 | R28: 75000 | S28: 75000
A29: G&A total | B29: =B24+B25+B26+B27+B28 | C29: =C24+C25+C26+C27+C28 | D29: =D24+D25+D26+D27+D28 | E29: =E24+E25+E26+E27+E28 | F29: =F24+F25+F26+F27+F28 | G29: =G24+G25+G26+G27+G28 | H29: =H24+H25+H26+H27+H28 | I29: =I24+I25+I26+I27+I28 | ... S29: =S24+S25+S26+S27+S28
A30: Operating expenses | B30: =B18+B23+B29 | C30: =C18+C23+C29 | D30: =D18+D23+D29 | E30: =E18+E23+E29 | F30: =F18+F23+F29 | G30: =G18+G23+G29 | H30: =H18+H23+H29 | I30: =I18+I23+I29 | ... S30: =S18+S23+S29
A31: EBITDA | B31: =B12-B30 | C31: =C12-C30 | D31: =D12-D30 | E31: =E12-E30 | F31: =F12-F30 | G31: =G12-G30 | H31: =H12-H30 | I31: =I12-I30 | ... S31: =S12-S30
A32: EBITDA margin | B32: =IF(B5=0,0,B31/B5) | C32: =IF(C5=0,0,C31/C5) | D32: =IF(D5=0,0,D31/D5) | E32: =IF(E5=0,0,E31/E5) | F32: =IF(F5=0,0,F31/F5) | G32: =IF(G5=0,0,G31/G5) | H32: =IF(H5=0,0,H31/H5) | I32: =IF(I5=0,0,I31/I5) | ... S32: =IF(S5=0,0,S31/S5)
A33: FTE total | B33: 139.16 | C33: 142.1 | D33: 146.02 | E33: 146.02 | F33: 153.86 | G33: 155.82 | H33: 157.78 | I33: 158.76 | J33: 160.72 | K33: 160.72 | L33: 161.7 | M33: 161.7 | N33: 161.7 | O33: 162.68 | P33: 162.68 | Q33: 162.68 | R33: 163.66 | S33: 163.66
A34: FTE customer operations | B34: 26.46 | C34: 26.46 | D34: 26.46 | E34: 26.46 | F34: 26.46 | G34: 26.46 | H34: 26.46 | I34: 26.46 | J34: 26.46 | K34: 26.46 | L34: 27.44 | M34: 27.44 | N34: 27.44 | O34: 28.42 | P34: 28.42 | Q34: 28.42 | R34: 29.4 | S34: 29.4
A35: FTE R&D | B35: 70.56 | C35: 72.52 | D35: 76.44 | E35: 76.44 | F35: 79.38 | G35: 80.36 | H35: 82.32 | I35: 82.32 | J35: 84.28 | K35: 84.28 | L35: 84.28 | M35: 84.28 | N35: 84.28 | O35: 84.28 | P35: 84.28 | Q35: 84.28 | R35: 84.28 | S35: 84.28
A36: FTE sales and marketing | B36: 27.44 | C36: 28.42 | D36: 28.42 | E36: 28.42 | F36: 32.34 | G36: 33.32 | H36: 33.32 | I36: 34.3 | J36: 34.3 | K36: 34.3 | L36: 34.3 | M36: 34.3 | N36: 34.3 | O36: 34.3 | P36: 34.3 | Q36: 34.3 | R36: 34.3 | S36: 34.3
A37: FTE G&A | B37: 14.7 | C37: 14.7 | D37: 14.7 | E37: 14.7 | F37: 15.68 | G37: 15.68 | H37: 15.68 | I37: 15.68 | J37: 15.68 | K37: 15.68 | L37: 15.68 | M37: 15.68 | N37: 15.68 | O37: 15.68 | P37: 15.68 | Q37: 15.68 | R37: 15.68 | S37: 15.68
A38: Total ARR (closing) | B38: 25068818 | C38: 25894278 | D38: 26707780 | E38: 27676964 | F38: 30254600 | G38: 31165669 | H38: 32231007 | I38: 33226564 | J38: 34314082 | K38: 35517008 | L38: 36520983 | M38: 37548377 | N38: 38775783 | O38: 40018843 | P38: 41230548 | Q38: 42648669 | R38: 46428110 | S38: 47700306
A39: Shaded yellow: values from the model. Shaded blue: Excel formulas.
A41: Plan upside: ARR roll-forward
...

Sheet Plan downside
A1: Plan downside: P&L
A2: USD, monthly | B2: 2026-09 | C2: 2026-10 | D2: 2026-11 | E2: 2026-12 | F2: 2027-01 | G2: 2027-02 | H2: 2027-03 | I2: 2027-04 | J2: 2027-05 | K2: 2027-06 | L2: 2027-07 | M2: 2027-08 | N2: 2027-09 | O2: 2027-10 | P2: 2027-11 | Q2: 2027-12 | R2: 2028-01 | S2: 2028-02
A3: Platform revenue | B3: 1867082.8 | C3: 1879003.8 | D3: 1890143.4 | E3: 1906182.6 | F3: 1973434.4 | G3: 1985450.1 | H3: 2002062.5 | I3: 2015448.5 | J3: 2031311.6 | K3: 2050327.3 | L3: 2062468.1 | M3: 2074880.8 | N3: 2093065.3 | O3: 2111140.2 | P3: 2127644.4 | Q3: 2149895.7 | R3: 2228529.2 | S3: 2243697.1
A4: Insights revenue | B4: 168269.3 | C4: 170641.7 | D4: 172961.43 | E4: 175816.63 | F4: 178013.34 | G4: 180471.18 | H4: 183438.73 | I4: 187127.8 | J4: 191131.77 | K4: 195538.27 | L4: 199236.93 | M4: 203010.39 | N4: 207500.31 | O4: 212041.43 | P4: 216458.06 | Q4: 221637.77 | R4: 225789.54 | S4: 230166.82
A5: Revenue | B5: =B3+B4 | C5: =C3+C4 | D5: =D3+D4 | E5: =E3+E4 | F5: =F3+F4 | G5: =G3+G4 | H5: =H3+H4 | I5: =I3+I4 | ... S5: =S3+S4
A6: Cloud hosting | B6: 148101.8 | C6: 148928.75 | D6: 149704.24 | E6: 150840.21 | F6: 151500.6 | G6: 152328.84 | H6: 153491.39 | I6: 154937.65 | J6: 156572.26 | K6: 158448.87 | L6: 159826.71 | M6: 161231.45 | N6: 163080.01 | O6: 164932 | P6: 166674.63 | Q6: 169197.91 | R6: 171220.25 | S6: 173398.58
A7: Third-party software and data | B7: 61060.562 | C7: 61489.364 | D7: 61893.144 | E7: 62459.976 | F7: 64543.431 | G7: 64977.638 | H7: 65565.038 | I7: 66077.289 | J7: 66673.303 | K7: 67375.966 | L7: 67851.151 | M7: 68336.737 | N7: 69016.97 | O7: 69695.449 | P7: 70323.074 | Q7: 71146.005 | R7: 73629.561 | S7: 74215.918
A8: Payment processing | B8: 30530.281 | C8: 30744.682 | D8: 30946.572 | E8: 31229.988 | F8: 32271.716 | G8: 32488.819 | H8: 32782.519 | I8: 33038.645 | J8: 33336.651 | K8: 33687.983 | L8: 33925.575 | M8: 34168.368 | N8: 34508.485 | O8: 34847.724 | P8: 35161.537 | Q8: 35573.003 | R8: 36814.78 | S8: 37107.959
A9: Customer operations payroll | B9: 276901.48 | C9: 276901.48 | D9: 276901.48 | E9: 276901.48 | F9: 286593.03 | G9: 286593.03 | H9: 286593.03 | I9: 286593.03 | J9: 286593.03 | K9: 286593.03 | L9: 286593.03 | M9: 286593.03 | N9: 286593.03 | O9: 286593.03 | P9: 286593.03 | Q9: 286593.03 | R9: 296623.79 | S9: 296623.79
A10: Customer operations recruiting | B10: 0 | C10: 0 | D10: 0 | E10: 0 | F10: 0 | G10: 0 | H10: 0 | I10: 0 | J10: 0 | K10: 0 | L10: 0 | M10: 0 | N10: 0 | O10: 0 | P10: 0 | Q10: 0 | R10: 0 | S10: 0
